Workbook

Sheet Summary
A1: DaVita Inc. (DVA): hand check against the 10-K
A3: Unit you type in ($ per unit) | B3: 1000 | C3: From the statement header: '$ in thousands'
A4: Match target | B4: 0.01
A5: Years | B5: FY2024, FY2025
A6: 10-K | B6: Filed 2026-02-11 (accession 0000927066-26-000012)
A8: How to use | B8: Each statement tab lists the statement exactly as the 10-K prints it. Open the 10-K at that statement and type every figure into the yellow cells as printed: a number in parentheses is negative, so (579,926) is typed as -579926. Leave a cell blank until you've checked it. Red = more than the target away from the tool's figure.
A9: Example | B9: Income statement tab, 'Dialysis patient service revenues', FY2025: the 10-K prints 13,007,186, so type 13007186. Under 'Page / note' write e.g. 'Consolidated Statements of Income, p. 72'.
A11: Tab | B11: Lines checked | C11: Within target | D11: Match rate
A12: Income statement | B12: {=COUNT('Income statement'!D6:D34)+COUNT('Income statement'!H6:H34)} -> 48 | C12: {=SUM('Income statement'!F6:F34)+SUM('Income statement'!J6:J34)} -> 48 | D12: {=IF(B12=0,"",C12/B12)} -> 1
A13: Balance sheet | B13: {=COUNT('Balance sheet'!D6:D50)+COUNT('Balance sheet'!H6:H50)} -> 82 | C13: {=SUM('Balance sheet'!F6:F50)+SUM('Balance sheet'!J6:J50)} -> 82 | D13: {=IF(B13=0,"",C13/B13)} -> 1
A14: Cash flow | B14: {=COUNT('Cash flow'!D6:D55)+COUNT('Cash flow'!H6:H55)} -> 90 | C14: {=SUM('Cash flow'!F6:F55)+SUM('Cash flow'!J6:J55)} -> 90 | D14: {=IF(B14=0,"",C14/B14)} -> 1
A15: Notes | B15: {=COUNT(Notes!D6:D9)+COUNT(Notes!H6:H9)} -> 0 | C15: {=SUM(Notes!F6:F9)+SUM(Notes!J6:J9)} -> 0 | D15: {=IF(B15=0,"",C15/B15)}
A16: All tabs | B16: {=SUM(B12:B15)} -> 220 | C16: {=SUM(C12:C15)} -> 220 | D16: {=IF(B16=0,"",C16/B16)} -> 1

Sheet Income statement
A1: CONSOLIDATED STATEMENTS OF INCOME (DaVita Inc.)
A2: As printed in the 10-K filed 2026-02-11: CONSOLIDATED STATEMENTS OF INCOME - USD ($) $ in Thousands. Yellow = type the 10-K figure. Blue = the tool's figure. Red = outside the target.
A3: Open this statement on SEC.gov
C4: FY2024 | G4: FY2025
A5: Line | B5: XBRL tag | C5: Tool | D5: 10-K | E5: Diff | F5: OK | G5: Tool | H5: 10-K | I5: Diff | J5: OK | K5: Page / note | L5: Note | M5: row id
A6: Income Statement [Abstract]
A7: Dialysis patient service revenues | B7: dva_RevenueFromContractWithCustomerIncludingAssessedTaxNetOfProvisionForUncollectibleAccounts | C7: {=12260375000/Summary!$B$3} -> 12260375 | D7: 12260375 | E7: {=IF(OR(D7="",C7=""),"",IF(D7=0,IF(C7=0,0,1),(C7-D7)/ABS(D7)))} -> 0 | F7: {=IF(E7="","",IF(ABS(E7)<=Summary!$B$4,1,0))} -> 1 | G7: {=13007186000/Summary!$B$3} -> 13007186 | H7: 13007186 | I7: {=IF(OR(H7="",G7=""),"",IF(H7=0,IF(G7=0,0,1),(G7-H7)/ABS(H7)))} -> 0 | J7: {=IF(I7="","",IF(ABS(I7)<=Summary!$B$4,1,0))} -> 1 | M7: income:1
A8: Other revenues | B8: us-gaap_OtherIncome | C8: {=555175000/Summary!$B$3} -> 555175 | D8: 555175 | E8: {=IF(OR(D8="",C8=""),"",IF(D8=0,IF(C8=0,0,1),(C8-D8)/ABS(D8)))} -> 0 | F8: {=IF(E8="","",IF(ABS(E8)<=Summary!$B$4,1,0))} -> 1 | G8: {=635883000/Summary!$B$3} -> 635883 | H8: 635883 | I8: {=IF(OR(H8="",G8=""),"",IF(H8=0,IF(G8=0,0,1),(G8-H8)/ABS(H8)))} -> 0 | J8: {=IF(I8="","",IF(ABS(I8)<=Summary!$B$4,1,0))} -> 1 | M8: income:2
A9: Total revenues | B9: us-gaap_Revenues | C9: {=12815550000/Summary!$B$3} -> 12815550 | D9: {=D7+D8} -> 12815550 | E9: {=IF(OR(D9="",C9=""),"",IF(D9=0,IF(C9=0,0,1),(C9-D9)/ABS(D9)))} -> 0 | F9: {=IF(E9="","",IF(ABS(E9)<=Summary!$B$4,1,0))} -> 1 | G9: {=13643069000/Summary!$B$3} -> 13643069 | H9: {=H7+H8} -> 13643069 | I9: {=IF(OR(H9="",G9=""),"",IF(H9=0,IF(G9=0,0,1),(G9-H9)/ABS(H9)))} -> 0 | J9: {=IF(I9="","",IF(ABS(I9)<=Summary!$B$4,1,0))} -> 1 | M9: income:3
A10: Operating expenses:
A11: Patient care costs | B11: dva_PatientCareCosts | C11: {=8598521000/Summary!$B$3} -> 8598521 | D11: 8598521 | E11: {=IF(OR(D11="",C11=""),"",IF(D11=0,IF(C11=0,0,1),(C11-D11)/ABS(D11)))} -> 0 | F11: {=IF(E11="","",IF(ABS(E11)<=Summary!$B$4,1,0))} -> 1 | G11: {=9243476000/Summary!$B$3} -> 9243476 | H11: 9243476 | I11: {=IF(OR(H11="",G11=""),"",IF(H11=0,IF(G11=0,0,1),(G11-H11)/ABS(H11)))} -> 0 | J11: {=IF(I11="","",IF(ABS(I11)<=Summary!$B$4,1,0))} -> 1 | M11: income:5
A12: General and administrative | B12: us-gaap_GeneralAndAdministrativeExpense | C12: {=1538341000/Summary!$B$3} -> 1538341 | D12: 1538341 | E12: {=IF(OR(D12="",C12=""),"",IF(D12=0,IF(C12=0,0,1),(C12-D12)/ABS(D12)))} -> 0 | F12: {=IF(E12="","",IF(ABS(E12)<=Summary!$B$4,1,0))} -> 1 | G12: {=1673630000/Summary!$B$3} -> 1673630 | H12: 1673630 | I12: {=IF(OR(H12="",G12=""),"",IF(H12=0,IF(G12=0,0,1),(G12-H12)/ABS(H12)))} -> 0 | J12: {=IF(I12="","",IF(ABS(I12)<=Summary!$B$4,1,0))} -> 1 | M12: income:6
A13: Depreciation and amortization | B13: us-gaap_DepreciationAndAmortization | C13: {=723860000/Summary!$B$3} -> 723860 | D13: 723860 | E13: {=IF(OR(D13="",C13=""),"",IF(D13=0,IF(C13=0,0,1),(C13-D13)/ABS(D13)))} -> 0 | F13: {=IF(E13="","",IF(ABS(E13)<=Summary!$B$4,1,0))} -> 1 | G13: {=715348000/Summary!$B$3} -> 715348 | H13: 715348 | I13: {=IF(OR(H13="",G13=""),"",IF(H13=0,IF(G13=0,0,1),(G13-H13)/ABS(H13)))} -> 0 | J13: {=IF(I13="","",IF(ABS(I13)<=Summary!$B$4,1,0))} -> 1 | M13: income:7
A14: Equity investment income, net | B14: us-gaap_IncomeLossFromEquityMethodInvestments | C14: {=-26189000/Summary!$B$3} -> -26189 | D14: -26189 | E14: {=IF(OR(D14="",C14=""),"",IF(D14=0,IF(C14=0,0,1),(C14-D14)/ABS(D14)))} -> 0 | F14: {=IF(E14="","",IF(ABS(E14)<=Summary!$B$4,1,0))} -> 1 | G14: {=-33000000/Summary!$B$3} -> -33000 | H14: -33000 | I14: {=IF(OR(H14="",G14=""),"",IF(H14=0,IF(G14=0,0,1),(G14-H14)/ABS(H14)))} -> 0 | J14: {=IF(I14="","",IF(ABS(I14)<=Summary!$B$4,1,0))} -> 1 | M14: income:8
A15: Goodwill impairment charges | B15: us-gaap_GoodwillImpairmentLoss | C15: {=0/Summary!$B$3} -> 0 | D15: 0 | E15: {=IF(OR(D15="",C15=""),"",IF(D15=0,IF(C15=0,0,1),(C15-D15)/ABS(D15)))} -> 0 | F15: {=IF(E15="","",IF(ABS(E15)<=Summary!$B$4,1,0))} -> 1 | G15: {=0/Summary!$B$3} -> 0 | H15: 0 | I15: {=IF(OR(H15="",G15=""),"",IF(H15=0,IF(G15=0,0,1),(G15-H15)/ABS(H15)))} -> 0 | J15: {=IF(I15="","",IF(ABS(I15)<=Summary!$B$4,1,0))} -> 1 | M15: income:9
A16: Gain on changes in ownership interests | B16: us-gaap_BusinessCombinationStepAcquisitionEquityInterestInAcquireeRemeasurementGain | C16: {=-109466000/Summary!$B$3} -> -109466 | D16: -109466 | E16: {=IF(OR(D16="",C16=""),"",IF(D16=0,IF(C16=0,0,1),(C16-D16)/ABS(D16)))} -> 0 | F16: {=IF(E16="","",IF(ABS(E16)<=Summary!$B$4,1,0))} -> 1 | G16: {=0/Summary!$B$3} -> 0 | H16: 0 | I16: {=IF(OR(H16="",G16=""),"",IF(H16=0,IF(G16=0,0,1),(G16-H16)/ABS(H16)))} -> 0 | J16: {=IF(I16="","",IF(ABS(I16)<=Summary!$B$4,1,0))} -> 1 | M16: income:10
A17: Total operating expenses | B17: us-gaap_CostsAndExpenses | C17: {=10725067000/Summary!$B$3} -> 10725067 | D17: {=D11+D12+D13+D14+D16} -> 10725067 | E17: {=IF(OR(D17="",C17=""),"",IF(D17=0,IF(C17=0,0,1),(C17-D17)/ABS(D17)))} -> 0 | F17: {=IF(E17="","",IF(ABS(E17)<=Summary!$B$4,1,0))} -> 1 | G17: {=11599454000/Summary!$B$3} -> 11599454 | H17: {=SUM(H11:H16)} -> 11599454 | I17: {=IF(OR(H17="",G17=""),"",IF(H17=0,IF(G17=0,0,1),(G17-H17)/ABS(H17)))} -> 0 | J17: {=IF(I17="","",IF(ABS(I17)<=Summary!$B$4,1,0))} -> 1 | M17: income:11
A18: Operating income | B18: us-gaap_OperatingIncomeLoss | C18: {=2090483000/Summary!$B$3} -> 2090483 | D18: {=D9-D17} -> 2090483 | E18: {=IF(OR(D18="",C18=""),"",IF(D18=0,IF(C18=0,0,1),(C18-D18)/ABS(D18)))} -> 0 | F18: {=IF(E18="","",IF(ABS(E18)<=Summary!$B$4,1,0))} -> 1 | G18: {=2043615000/Summary!$B$3} -> 2043615 | H18: {=H9-H17} -> 2043615 | I18: {=IF(OR(H18="",G18=""),"",IF(H18=0,IF(G18=0,0,1),(G18-H18)/ABS(H18)))} -> 0 | J18: {=IF(I18="","",IF(ABS(I18)<=Summary!$B$4,1,0))} -> 1 | M18: income:12
A19: Debt expense | B19: us-gaap_InterestAndDebtExpense | C19: {=-470469000/Summary!$B$3} -> -470469 | D19: -470469 | E19: {=IF(OR(D19="",C19=""),"",IF(D19=0,IF(C19=0,0,1),(C19-D19)/ABS(D19)))} -> 0 | F19: {=IF(E19="","",IF(ABS(E19)<=Summary!$B$4,1,0))} -> 1 | G19: {=-579926000/Summary!$B$3} -> -579926 | H19: -579926 | I19: {=IF(OR(H19="",G19=""),"",IF(H19=0,IF(G19=0,0,1),(G19-H19)/ABS(H19)))} -> 0 | J19: {=IF(I19="","",IF(ABS(I19)<=Summary!$B$4,1,0))} -> 1 | M19: income:13
A20: Debt extinguishment and modification costs | B20: dva_DebtPrepaymentExtinguishmentAndModificationCosts | C20: {=-19813000/Summary!$B$3} -> -19813 | D20: -19813 | E20: {=IF(OR(D20="",C20=""),"",IF(D20=0,IF(C20=0,0,1),(C20-D20)/ABS(D20)))} -> 0 | F20: {=IF(E20="","",IF(ABS(E20)<=Summary!$B$4,1,0))} -> 1 | G20: {=-14178000/Summary!$B$3} -> -14178 | H20: -14178 | I20: {=IF(OR(H20="",G20=""),"",IF(H20=0,IF(G20=0,0,1),(G20-H20)/ABS(H20)))} -> 0 | J20: {=IF(I20="","",IF(ABS(I20)<=Summary!$B$4,1,0))} -> 1 | M20: income:14
A21: Other loss, net | B21: us-gaap_OtherNonoperatingIncomeExpense | C21: {=-69808000/Summary!$B$3} -> -69808 | D21: -69808 | E21: {=IF(OR(D21="",C21=""),"",IF(D21=0,IF(C21=0,0,1),(C21-D21)/ABS(D21)))} -> 0 | F21: {=IF(E21="","",IF(ABS(E21)<=Summary!$B$4,1,0))} -> 1 | G21: {=-102688000/Summary!$B$3} -> -102688 | H21: -102688 | I21: {=IF(OR(H21="",G21=""),"",IF(H21=0,IF(G21=0,0,1),(G21-H21)/ABS(H21)))} -> 0 | J21: {=IF(I21="","",IF(ABS(I21)<=Summary!$B$4,1,0))} -> 1 | M21: income:15
A22: Income from continuing operations before income taxes | B22: us-gaap_IncomeLossFromContinuingOperationsBeforeIncomeTaxesExtraordinaryItemsNoncontrollingInterest | C22: {=1530393000/Summary!$B$3} -> 1530393 | D22: {=D18+D19+D20+D21} -> 1530393 | E22: {=IF(OR(D22="",C22=""),"",IF(D22=0,IF(C22=0,0,1),(C22-D22)/ABS(D22)))} -> 0 | F22: {=IF(E22="","",IF(ABS(E22)<=Summary!$B$4,1,0))} -> 1 | G22: {=1346823000/Summary!$B$3} -> 1346823 | H22: {=SUM(H18:H21)} -> 1346823 | I22: {=IF(OR(H22="",G22=""),"",IF(H22=0,IF(G22=0,0,1),(G22-H22)/ABS(H22)))} -> 0 | J22: {=IF(I22="","",IF(ABS(I22)<=Summary!$B$4,1,0))} -> 1 | M22: income:16
A23: Income tax expense | B23: us-gaap_IncomeTaxExpenseBenefit | C23: {=279656000/Summary!$B$3} -> 279656 | D23: 279656 | E23: {=IF(OR(D23="",C23=""),"",IF(D23=0,IF(C23=0,0,1),(C23-D23)/ABS(D23)))} -> 0 | F23: {=IF(E23="","",IF(ABS(E23)<=Summary!$B$4,1,0))} -> 1 | G23: {=293107000/Summary!$B$3} -> 293107 | H23: 293107 | I23: {=IF(OR(H23="",G23=""),"",IF(H23=0,IF(G23=0,0,1),(G23-H23)/ABS(H23)))} -> 0 | J23: {=IF(I23="","",IF(ABS(I23)<=Summary!$B$4,1,0))} -> 1 | M23: income:17
A24: Net income from continuing operations | B24: us-gaap_IncomeLossFromContinuingOperationsIncludingPortionAttributableToNoncontrollingInterest | C24: {=1250737000/Summary!$B$3} -> 1250737 | D24: {=D22-D23} -> 1250737 | E24: {=IF(OR(D24="",C24=""),"",IF(D24=0,IF(C24=0,0,1),(C24-D24)/ABS(D24)))} -> 0 | F24: {=IF(E24="","",IF(ABS(E24)<=Summary!$B$4,1,0))} -> 1 | G24: {=1053716000/Summary!$B$3} -> 1053716 | H24: {=H22-H23} -> 1053716 | I24: {=IF(OR(H24="",G24=""),"",IF(H24=0,IF(G24=0,0,1),(G24-H24)/ABS(H24)))} -> 0 | J24: {=IF(I24="","",IF(ABS(I24)<=Summary!$B$4,1,0))} -> 1 | M24: income:18
A25: Net income from discontinued operations, net of tax | B25: us-gaap_IncomeLossFromDiscontinuedOperationsNetOfTax | C25: {=0/Summary!$B$3} -> 0 | D25: 0 | E25: {=IF(OR(D25="",C25=""),"",IF(D25=0,IF(C25=0,0,1),(C25-D25)/ABS(D25)))} -> 0 | F25: {=IF(E25="","",IF(ABS(E25)<=Summary!$B$4,1,0))} -> 1 | G25: {=25000000/Summary!$B$3} -> 25000 | H25: 25000 | I25: {=IF(OR(H25="",G25=""),"",IF(H25=0,IF(G25=0,0,1),(G25-H25)/ABS(H25)))} -> 0 | J25: {=IF(I25="","",IF(ABS(I25)<=Summary!$B$4,1,0))} -> 1 | M25: income:19
A26: Net income | B26: us-gaap_ProfitLoss | C26: {=1250737000/Summary!$B$3} -> 1250737 | D26: {=D24+D25} -> 1250737 | E26: {=IF(OR(D26="",C26=""),"",IF(D26=0,IF(C26=0,0,1),(C26-D26)/ABS(D26)))} -> 0 | F26: {=IF(E26="","",IF(ABS(E26)<=Summary!$B$4,1,0))} -> 1 | G26: {=1078716000/Summary!$B$3} -> 1078716 | H26: {=SUM(H24:H25)} -> 1078716 | I26: {=IF(OR(H26="",G26=""),"",IF(H26=0,IF(G26=0,0,1),(G26-H26)/ABS(H26)))} -> 0 | J26: {=IF(I26="","",IF(ABS(I26)<=Summary!$B$4,1,0))} -> 1 | M26: income:20
A27: Less: Net income attributable to noncontrolling interests | B27: us-gaap_NetIncomeLossAttributableToNoncontrollingInterest | C27: {=-314395000/Summary!$B$3} -> -314395 | D27: -314395 | E27: {=IF(OR(D27="",C27=""),"",IF(D27=0,IF(C27=0,0,1),(C27-D27)/ABS(D27)))} -> 0 | F27: {=IF(E27="","",IF(ABS(E27)<=Summary!$B$4,1,0))} -> 1 | G27: {=-331913000/Summary!$B$3} -> -331913 | H27: -331913 | I27: {=IF(OR(H27="",G27=""),"",IF(H27=0,IF(G27=0,0,1),(G27-H27)/ABS(H27)))} -> 0 | J27: {=IF(I27="","",IF(ABS(I27)<=Summary!$B$4,1,0))} -> 1 | M27: income:21
A28: Net income attributable to DaVita Inc. | B28: us-gaap_NetIncomeLoss | C28: {=936342000/Summary!$B$3} -> 936342 | D28: {=D26+D27} -> 936342 | E28: {=IF(OR(D28="",C28=""),"",IF(D28=0,IF(C28=0,0,1),(C28-D28)/ABS(D28)))} -> 0 | F28: {=IF(E28="","",IF(ABS(E28)<=Summary!$B$4,1,0))} -> 1 | G28: {=746803000/Summary!$B$3} -> 746803 | H28: {=SUM(H26:H27)} -> 746803 | I28: {=IF(OR(H28="",G28=""),"",IF(H28=0,IF(G28=0,0,1),(G28-H28)/ABS(H28)))} -> 0 | J28: {=IF(I28="","",IF(ABS(I28)<=Summary!$B$4,1,0))} -> 1 | M28: income:22
A29: Earnings per share attributable to DaVita Inc.:
A30: Weighted average shares for earnings per share:
A31: Amounts attributable to DaVita Inc.:
A32: Net income from continuing operations | B32: us-gaap_IncomeLossFromContinuingOperations | C32: {=936342000/Summary!$B$3} -> 936342 | D32: {=D28} -> 936342 | E32: {=IF(OR(D32="",C32=""),"",IF(D32=0,IF(C32=0,0,1),(C32-D32)/ABS(D32)))} -> 0 | F32: {=IF(E32="","",IF(ABS(E32)<=Summary!$B$4,1,0))} -> 1 | G32: {=721803000/Summary!$B$3} -> 721803 | H32: 721803 | I32: {=IF(OR(H32="",G32=""),"",IF(H32=0,IF(G32=0,0,1),(G32-H32)/ABS(H32)))} -> 0 | J32: {=IF(I32="","",IF(ABS(I32)<=Summary!$B$4,1,0))} -> 1 | M32: income:32
A33: Net income from discontinued operations | B33: us-gaap_IncomeLossFromDiscontinuedOperationsNetOfTaxAttributableToReportingEntity | C33: {=0/Summary!$B$3} -> 0 | D33: 0 | E33: {=IF(OR(D33="",C33=""),"",IF(D33=0,IF(C33=0,0,1),(C33-D33)/ABS(D33)))} -> 0 | F33: {=IF(E33="","",IF(ABS(E33)<=Summary!$B$4,1,0))} -> 1 | G33: {=25000000/Summary!$B$3} -> 25000 | H33: 25000 | I33: {=IF(OR(H33="",G33=""),"",IF(H33=0,IF(G33=0,0,1),(G33-H33)/ABS(H33)))} -> 0 | J33: {=IF(I33="","",IF(ABS(I33)<=Summary!$B$4,1,0))} -> 1 | M33: income:33
A34: Net income attributable to DaVita Inc. | B34: us-gaap_NetIncomeLoss | C34: {=936342000/Summary!$B$3} -> 936342 | D34: {=D32+D33} -> 936342 | E34: {=IF(OR(D34="",C34=""),"",IF(D34=0,IF(C34=0,0,1),(C34-D34)/ABS(D34)))} -> 0 | F34: {=IF(E34="","",IF(ABS(E34)<=Summary!$B$4,1,0))} -> 1 | G34: {=746803000/Summary!$B$3} -> 746803 | H34: {=SUM(H32:H33)} -> 746803 | I34: {=IF(OR(H34="",G34=""),"",IF(H34=0,IF(G34=0,0,1),(G34-H34)/ABS(H34)))} -> 0 | J34: {=IF(I34="","",IF(ABS(I34)<=Summary!$B$4,1,0))} -> 1 | M34: income:34

Sheet Balance sheet
A1: CONSOLIDATED BALANCE SHEETS (DaVita Inc.)
A2: As printed in the 10-K filed 2026-02-11: CONSOLIDATED BALANCE SHEETS - USD ($) $ in Thousands. Yellow = type the 10-K figure. Blue = the tool's figure. Red = outside the target.
A3: Open this statement on SEC.gov
C4: FY2024 | G4: FY2025
A5: Line | B5: XBRL tag | C5: Tool | D5: 10-K | E5: Diff | F5: OK | G5: Tool | H5: 10-K | I5: Diff | J5: OK | K5: Page / note | L5: Note | M5: row id
A6: ASSETS
A7: Cash and cash equivalents | B7: us-gaap_CashAndCashEquivalentsAtCarryingValue | C7: {=794933000/Summary!$B$3} -> 794933 | D7: 794933 | E7: {=IF(OR(D7="",C7=""),"",IF(D7=0,IF(C7=0,0,1),(C7-D7)/ABS(D7)))} -> 0 | F7: {=IF(E7="","",IF(ABS(E7)<=Summary!$B$4,1,0))} -> 1 | G7: {=676438000/Summary!$B$3} -> 676438 | H7: 676438 | I7: {=IF(OR(H7="",G7=""),"",IF(H7=0,IF(G7=0,0,1),(G7-H7)/ABS(H7)))} -> 0 | J7: {=IF(I7="","",IF(ABS(I7)<=Summary!$B$4,1,0))} -> 1 | M7: balance:1
A8: Restricted cash and equivalents | B8: us-gaap_RestrictedCashAndCashEquivalents | C8: {=84892000/Summary!$B$3} -> 84892 | D8: 84892 | E8: {=IF(OR(D8="",C8=""),"",IF(D8=0,IF(C8=0,0,1),(C8-D8)/ABS(D8)))} -> 0 | F8: {=IF(E8="","",IF(ABS(E8)<=Summary!$B$4,1,0))} -> 1 | G8: {=81309000/Summary!$B$3} -> 81309 | H8: 81309 | I8: {=IF(OR(H8="",G8=""),"",IF(H8=0,IF(G8=0,0,1),(G8-H8)/ABS(H8)))} -> 0 | J8: {=IF(I8="","",IF(ABS(I8)<=Summary!$B$4,1,0))} -> 1 | M8: balance:2
A9: Short-term investments | B9: us-gaap_MarketableSecuritiesCurrent | C9: {=51064000/Summary!$B$3} -> 51064 | D9: 51064 | E9: {=IF(OR(D9="",C9=""),"",IF(D9=0,IF(C9=0,0,1),(C9-D9)/ABS(D9)))} -> 0 | F9: {=IF(E9="","",IF(ABS(E9)<=Summary!$B$4,1,0))} -> 1 | G9: {=24303000/Summary!$B$3} -> 24303 | H9: 24303 | I9: {=IF(OR(H9="",G9=""),"",IF(H9=0,IF(G9=0,0,1),(G9-H9)/ABS(H9)))} -> 0 | J9: {=IF(I9="","",IF(ABS(I9)<=Summary!$B$4,1,0))} -> 1 | M9: balance:3
A10: Accounts receivable | B10: us-gaap_AccountsReceivableNetCurrent | C10: {=2146975000/Summary!$B$3} -> 2146975 | D10: 2146975 | E10: {=IF(OR(D10="",C10=""),"",IF(D10=0,IF(C10=0,0,1),(C10-D10)/ABS(D10)))} -> 0 | F10: {=IF(E10="","",IF(ABS(E10)<=Summary!$B$4,1,0))} -> 1 | G10: {=2414690000/Summary!$B$3} -> 2414690 | H10: 2414690 | I10: {=IF(OR(H10="",G10=""),"",IF(H10=0,IF(G10=0,0,1),(G10-H10)/ABS(H10)))} -> 0 | J10: {=IF(I10="","",IF(ABS(I10)<=Summary!$B$4,1,0))} -> 1 | M10: balance:4
A11: Inventories | B11: us-gaap_InventoryNet | C11: {=134559000/Summary!$B$3} -> 134559 | D11: 134559 | E11: {=IF(OR(D11="",C11=""),"",IF(D11=0,IF(C11=0,0,1),(C11-D11)/ABS(D11)))} -> 0 | F11: {=IF(E11="","",IF(ABS(E11)<=Summary!$B$4,1,0))} -> 1 | G11: {=160627000/Summary!$B$3} -> 160627 | H11: 160627 | I11: {=IF(OR(H11="",G11=""),"",IF(H11=0,IF(G11=0,0,1),(G11-H11)/ABS(H11)))} -> 0 | J11: {=IF(I11="","",IF(ABS(I11)<=Summary!$B$4,1,0))} -> 1 | M11: balance:5
A12: Contract assets and other receivables | B12: us-gaap_OtherReceivablesNetCurrent | C12: {=383166000/Summary!$B$3} -> 383166 | D12: 383166 | E12: {=IF(OR(D12="",C12=""),"",IF(D12=0,IF(C12=0,0,1),(C12-D12)/ABS(D12)))} -> 0 | F12: {=IF(E12="","",IF(ABS(E12)<=Summary!$B$4,1,0))} -> 1 | G12: {=494414000/Summary!$B$3} -> 494414 | H12: 494414 | I12: {=IF(OR(H12="",G12=""),"",IF(H12=0,IF(G12=0,0,1),(G12-H12)/ABS(H12)))} -> 0 | J12: {=IF(I12="","",IF(ABS(I12)<=Summary!$B$4,1,0))} -> 1 | M12: balance:6
A13: Prepaid and other current assets | B13: us-gaap_PrepaidExpenseAndOtherAssetsCurrent | C13: {=122948000/Summary!$B$3} -> 122948 | D13: 122948 | E13: {=IF(OR(D13="",C13=""),"",IF(D13=0,IF(C13=0,0,1),(C13-D13)/ABS(D13)))} -> 0 | F13: {=IF(E13="","",IF(ABS(E13)<=Summary!$B$4,1,0))} -> 1 | G13: {=156285000/Summary!$B$3} -> 156285 | H13: 156285 | I13: {=IF(OR(H13="",G13=""),"",IF(H13=0,IF(G13=0,0,1),(G13-H13)/ABS(H13)))} -> 0 | J13: {=IF(I13="","",IF(ABS(I13)<=Summary!$B$4,1,0))} -> 1 | M13: balance:7
A14: Income tax receivable | B14: us-gaap_IncomeTaxesReceivable | C14: {=27535000/Summary!$B$3} -> 27535 | D14: 27535 | E14: {=IF(OR(D14="",C14=""),"",IF(D14=0,IF(C14=0,0,1),(C14-D14)/ABS(D14)))} -> 0 | F14: {=IF(E14="","",IF(ABS(E14)<=Summary!$B$4,1,0))} -> 1 | G14: {=49937000/Summary!$B$3} -> 49937 | H14: 49937 | I14: {=IF(OR(H14="",G14=""),"",IF(H14=0,IF(G14=0,0,1),(G14-H14)/ABS(H14)))} -> 0 | J14: {=IF(I14="","",IF(ABS(I14)<=Summary!$B$4,1,0))} -> 1 | M14: balance:8
A15: Total current assets | B15: us-gaap_AssetsCurrent | C15: {=3746072000/Summary!$B$3} -> 3746072 | D15: {=SUM(D7:D14)} -> 3746072 | E15: {=IF(OR(D15="",C15=""),"",IF(D15=0,IF(C15=0,0,1),(C15-D15)/ABS(D15)))} -> 0 | F15: {=IF(E15="","",IF(ABS(E15)<=Summary!$B$4,1,0))} -> 1 | G15: {=4058003000/Summary!$B$3} -> 4058003 | H15: {=SUM(H7:H14)} -> 4058003 | I15: {=IF(OR(H15="",G15=""),"",IF(H15=0,IF(G15=0,0,1),(G15-H15)/ABS(H15)))} -> 0 | J15: {=IF(I15="","",IF(ABS(I15)<=Summary!$B$4,1,0))} -> 1 | M15: balance:9
A16: Property and equipment, net of accumulated depreciation | B16: us-gaap_PropertyPlantAndEquipmentNet | C16: {=2940916000/Summary!$B$3} -> 2940916 | D16: 2940916 | E16: {=IF(OR(D16="",C16=""),"",IF(D16=0,IF(C16=0,0,1),(C16-D16)/ABS(D16)))} -> 0 | F16: {=IF(E16="","",IF(ABS(E16)<=Summary!$B$4,1,0))} -> 1 | G16: {=2812966000/Summary!$B$3} -> 2812966 | H16: 2812966 | I16: {=IF(OR(H16="",G16=""),"",IF(H16=0,IF(G16=0,0,1),(G16-H16)/ABS(H16)))} -> 0 | J16: {=IF(I16="","",IF(ABS(I16)<=Summary!$B$4,1,0))} -> 1 | M16: balance:10
A17: Operating lease right-of-use assets | B17: us-gaap_OperatingLeaseRightOfUseAsset | C17: {=2393558000/Summary!$B$3} -> 2393558 | D17: 2393558 | E17: {=IF(OR(D17="",C17=""),"",IF(D17=0,IF(C17=0,0,1),(C17-D17)/ABS(D17)))} -> 0 | F17: {=IF(E17="","",IF(ABS(E17)<=Summary!$B$4,1,0))} -> 1 | G17: {=2397179000/Summary!$B$3} -> 2397179 | H17: 2397179 | I17: {=IF(OR(H17="",G17=""),"",IF(H17=0,IF(G17=0,0,1),(G17-H17)/ABS(H17)))} -> 0 | J17: {=IF(I17="","",IF(ABS(I17)<=Summary!$B$4,1,0))} -> 1 | M17: balance:11
A18: Intangible assets, net of accumulated amortization | B18: us-gaap_IntangibleAssetsNetExcludingGoodwill | C18: {=197431000/Summary!$B$3} -> 197431 | D18: 197431 | E18: {=IF(OR(D18="",C18=""),"",IF(D18=0,IF(C18=0,0,1),(C18-D18)/ABS(D18)))} -> 0 | F18: {=IF(E18="","",IF(ABS(E18)<=Summary!$B$4,1,0))} -> 1 | G18: {=222125000/Summary!$B$3} -> 222125 | H18: 222125 | I18: {=IF(OR(H18="",G18=""),"",IF(H18=0,IF(G18=0,0,1),(G18-H18)/ABS(H18)))} -> 0 | J18: {=IF(I18="","",IF(ABS(I18)<=Summary!$B$4,1,0))} -> 1 | M18: balance:12
A19: Equity method and other investments | B19: us-gaap_InvestmentsInAffiliatesSubsidiariesAssociatesAndJointVentures | C19: {=336684000/Summary!$B$3} -> 336684 | D19: 336684 | E19: {=IF(OR(D19="",C19=""),"",IF(D19=0,IF(C19=0,0,1),(C19-D19)/ABS(D19)))} -> 0 | F19: {=IF(E19="","",IF(ABS(E19)<=Summary!$B$4,1,0))} -> 1 | G19: {=157249000/Summary!$B$3} -> 157249 | H19: 157249 | I19: {=IF(OR(H19="",G19=""),"",IF(H19=0,IF(G19=0,0,1),(G19-H19)/ABS(H19)))} -> 0 | J19: {=IF(I19="","",IF(ABS(I19)<=Summary!$B$4,1,0))} -> 1 | M19: balance:13
A20: Long-term investments | B20: us-gaap_MarketableSecuritiesNoncurrent | C20: {=33660000/Summary!$B$3} -> 33660 | D20: 33660 | E20: {=IF(OR(D20="",C20=""),"",IF(D20=0,IF(C20=0,0,1),(C20-D20)/ABS(D20)))} -> 0 | F20: {=IF(E20="","",IF(ABS(E20)<=Summary!$B$4,1,0))} -> 1 | G20: {=40966000/Summary!$B$3} -> 40966 | H20: 40966 | I20: {=IF(OR(H20="",G20=""),"",IF(H20=0,IF(G20=0,0,1),(G20-H20)/ABS(H20)))} -> 0 | J20: {=IF(I20="","",IF(ABS(I20)<=Summary!$B$4,1,0))} -> 1 | M20: balance:14
A21: Other long-term assets | B21: us-gaap_OtherAssetsNoncurrent | C21: {=261731000/Summary!$B$3} -> 261731 | D21: 261731 | E21: {=IF(OR(D21="",C21=""),"",IF(D21=0,IF(C21=0,0,1),(C21-D21)/ABS(D21)))} -> 0 | F21: {=IF(E21="","",IF(ABS(E21)<=Summary!$B$4,1,0))} -> 1 | G21: {=246520000/Summary!$B$3} -> 246520 | H21: 246520 | I21: {=IF(OR(H21="",G21=""),"",IF(H21=0,IF(G21=0,0,1),(G21-H21)/ABS(H21)))} -> 0 | J21: {=IF(I21="","",IF(ABS(I21)<=Summary!$B$4,1,0))} -> 1 | M21: balance:15
A22: Goodwill | B22: us-gaap_Goodwill | C22: {=7375216000/Summary!$B$3} -> 7375216 | D22: 7375216 | E22: {=IF(OR(D22="",C22=""),"",IF(D22=0,IF(C22=0,0,1),(C22-D22)/ABS(D22)))} -> 0 | F22: {=IF(E22="","",IF(ABS(E22)<=Summary!$B$4,1,0))} -> 1 | G22: {=7545095000/Summary!$B$3} -> 7545095 | H22: 7545095 | I22: {=IF(OR(H22="",G22=""),"",IF(H22=0,IF(G22=0,0,1),(G22-H22)/ABS(H22)))} -> 0 | J22: {=IF(I22="","",IF(ABS(I22)<=Summary!$B$4,1,0))} -> 1 | M22: balance:16
A23: Assets, Total | B23: us-gaap_Assets | C23: {=17285268000/Summary!$B$3} -> 17285268 | D23: {=SUM(D15:D22)} -> 17285268 | E23: {=IF(OR(D23="",C23=""),"",IF(D23=0,IF(C23=0,0,1),(C23-D23)/ABS(D23)))} -> 0 | F23: {=IF(E23="","",IF(ABS(E23)<=Summary!$B$4,1,0))} -> 1 | G23: {=17480103000/Summary!$B$3} -> 17480103 | H23: {=SUM(H15:H22)} -> 17480103 | I23: {=IF(OR(H23="",G23=""),"",IF(H23=0,IF(G23=0,0,1),(G23-H23)/ABS(H23)))} -> 0 | J23: {=IF(I23="","",IF(ABS(I23)<=Summary!$B$4,1,0))} -> 1 | M23: balance:17
A24: LIABILITIES AND EQUITY
A25: Accounts payable | B25: us-gaap_AccountsPayableCurrent | C25: {=547200000/Summary!$B$3} -> 547200 | D25: 547200 | E25: {=IF(OR(D25="",C25=""),"",IF(D25=0,IF(C25=0,0,1),(C25-D25)/ABS(D25)))} -> 0 | F25: {=IF(E25="","",IF(ABS(E25)<=Summary!$B$4,1,0))} -> 1 | G25: {=696148000/Summary!$B$3} -> 696148 | H25: 696148 | I25: {=IF(OR(H25="",G25=""),"",IF(H25=0,IF(G25=0,0,1),(G25-H25)/ABS(H25)))} -> 0 | J25: {=IF(I25="","",IF(ABS(I25)<=Summary!$B$4,1,0))} -> 1 | M25: balance:19
A26: Other liabilities | B26: us-gaap_OtherLiabilitiesCurrent | C26: {=934145000/Summary!$B$3} -> 934145 | D26: 934145 | E26: {=IF(OR(D26="",C26=""),"",IF(D26=0,IF(C26=0,0,1),(C26-D26)/ABS(D26)))} -> 0 | F26: {=IF(E26="","",IF(ABS(E26)<=Summary!$B$4,1,0))} -> 1 | G26: {=893024000/Summary!$B$3} -> 893024 | H26: 893024 | I26: {=IF(OR(H26="",G26=""),"",IF(H26=0,IF(G26=0,0,1),(G26-H26)/ABS(H26)))} -> 0 | J26: {=IF(I26="","",IF(ABS(I26)<=Summary!$B$4,1,0))} -> 1 | M26: balance:20
A27: Accrued compensation and benefits | B27: us-gaap_EmployeeRelatedLiabilitiesCurrent | C27: {=800484000/Summary!$B$3} -> 800484 | D27: 800484 | E27: {=IF(OR(D27="",C27=""),"",IF(D27=0,IF(C27=0,0,1),(C27-D27)/ABS(D27)))} -> 0 | F27: {=IF(E27="","",IF(ABS(E27)<=Summary!$B$4,1,0))} -> 1 | G27: {=793478000/Summary!$B$3} -> 793478 | H27: 793478 | I27: {=IF(OR(H27="",G27=""),"",IF(H27=0,IF(G27=0,0,1),(G27-H27)/ABS(H27)))} -> 0 | J27: {=IF(I27="","",IF(ABS(I27)<=Summary!$B$4,1,0))} -> 1 | M27: balance:21
A28: Current portion of operating lease liabilities | B28: us-gaap_OperatingLeaseLiabilityCurrent | C28: {=410411000/Summary!$B$3} -> 410411 | D28: 410411 | E28: {=IF(OR(D28="",C28=""),"",IF(D28=0,IF(C28=0,0,1),(C28-D28)/ABS(D28)))} -> 0 | F28: {=IF(E28="","",IF(ABS(E28)<=Summary!$B$4,1,0))} -> 1 | G28: {=425484000/Summary!$B$3} -> 425484 | H28: 425484 | I28: {=IF(OR(H28="",G28=""),"",IF(H28=0,IF(G28=0,0,1),(G28-H28)/ABS(H28)))} -> 0 | J28: {=IF(I28="","",IF(ABS(I28)<=Summary!$B$4,1,0))} -> 1 | M28: balance:22
A29: Current portion of long-term debt | B29: us-gaap_LongTermDebtAndCapitalLeaseObligationsCurrent | C29: {=270867000/Summary!$B$3} -> 270867 | D29: 270867 | E29: {=IF(OR(D29="",C29=""),"",IF(D29=0,IF(C29=0,0,1),(C29-D29)/ABS(D29)))} -> 0 | F29: {=IF(E29="","",IF(ABS(E29)<=Summary!$B$4,1,0))} -> 1 | G29: {=109201000/Summary!$B$3} -> 109201 | H29: 109201 | I29: {=IF(OR(H29="",G29=""),"",IF(H29=0,IF(G29=0,0,1),(G29-H29)/ABS(H29)))} -> 0 | J29: {=IF(I29="","",IF(ABS(I29)<=Summary!$B$4,1,0))} -> 1 | M29: balance:23
A30: Income tax payable | B30: us-gaap_AccruedIncomeTaxesCurrent | C30: {=10303000/Summary!$B$3} -> 10303 | D30: 10303 | E30: {=IF(OR(D30="",C30=""),"",IF(D30=0,IF(C30=0,0,1),(C30-D30)/ABS(D30)))} -> 0 | F30: {=IF(E30="","",IF(ABS(E30)<=Summary!$B$4,1,0))} -> 1 | G30: {=24359000/Summary!$B$3} -> 24359 | H30: 24359 | I30: {=IF(OR(H30="",G30=""),"",IF(H30=0,IF(G30=0,0,1),(G30-H30)/ABS(H30)))} -> 0 | J30: {=IF(I30="","",IF(ABS(I30)<=Summary!$B$4,1,0))} -> 1 | M30: balance:24
A31: Due to Related Party | B31: dva_DueToRelatedParty | C31: {=0/Summary!$B$3} -> 0 | D31: 0 | E31: {=IF(OR(D31="",C31=""),"",IF(D31=0,IF(C31=0,0,1),(C31-D31)/ABS(D31)))} -> 0 | F31: {=IF(E31="","",IF(ABS(E31)<=Summary!$B$4,1,0))} -> 1 | G31: {=199940000/Summary!$B$3} -> 199940 | H31: 199940 | I31: {=IF(OR(H31="",G31=""),"",IF(H31=0,IF(G31=0,0,1),(G31-H31)/ABS(H31)))} -> 0 | J31: {=IF(I31="","",IF(ABS(I31)<=Summary!$B$4,1,0))} -> 1 | M31: balance:25
A32: Total current liabilities | B32: us-gaap_LiabilitiesCurrent | C32: {=2973410000/Summary!$B$3} -> 2973410 | D32: {=SUM(D25:D31)} -> 2973410 | E32: {=IF(OR(D32="",C32=""),"",IF(D32=0,IF(C32=0,0,1),(C32-D32)/ABS(D32)))} -> 0 | F32: {=IF(E32="","",IF(ABS(E32)<=Summary!$B$4,1,0))} -> 1 | G32: {=3141634000/Summary!$B$3} -> 3141634 | H32: {=SUM(H25:H31)} -> 3141634 | I32: {=IF(OR(H32="",G32=""),"",IF(H32=0,IF(G32=0,0,1),(G32-H32)/ABS(H32)))} -> 0 | J32: {=IF(I32="","",IF(ABS(I32)<=Summary!$B$4,1,0))} -> 1 | M32: balance:26
A33: Long-term operating lease liabilities | B33: us-gaap_OperatingLeaseLiabilityNoncurrent | C33: {=2209655000/Summary!$B$3} -> 2209655 | D33: 2209655 | E33: {=IF(OR(D33="",C33=""),"",IF(D33=0,IF(C33=0,0,1),(C33-D33)/ABS(D33)))} -> 0 | F33: {=IF(E33="","",IF(ABS(E33)<=Summary!$B$4,1,0))} -> 1 | G33: {=2175658000/Summary!$B$3} -> 2175658 | H33: 2175658 | I33: {=IF(OR(H33="",G33=""),"",IF(H33=0,IF(G33=0,0,1),(G33-H33)/ABS(H33)))} -> 0 | J33: {=IF(I33="","",IF(ABS(I33)<=Summary!$B$4,1,0))} -> 1 | M33: balance:27
A34: Long-term debt | B34: us-gaap_LongTermDebtAndCapitalLeaseObligations | C34: {=9175903000/Summary!$B$3} -> 9175903 | D34: 9175903 | E34: {=IF(OR(D34="",C34=""),"",IF(D34=0,IF(C34=0,0,1),(C34-D34)/ABS(D34)))} -> 0 | F34: {=IF(E34="","",IF(ABS(E34)<=Summary!$B$4,1,0))} -> 1 | G34: {=10163988000/Summary!$B$3} -> 10163988 | H34: 10163988 | I34: {=IF(OR(H34="",G34=""),"",IF(H34=0,IF(G34=0,0,1),(G34-H34)/ABS(H34)))} -> 0 | J34: {=IF(I34="","",IF(ABS(I34)<=Summary!$B$4,1,0))} -> 1 | M34: balance:28
A35: Other long-term liabilities | B35: us-gaap_OtherLiabilitiesNoncurrent | C35: {=169588000/Summary!$B$3} -> 169588 | D35: 169588 | E35: {=IF(OR(D35="",C35=""),"",IF(D35=0,IF(C35=0,0,1),(C35-D35)/ABS(D35)))} -> 0 | F35: {=IF(E35="","",IF(ABS(E35)<=Summary!$B$4,1,0))} -> 1 | G35: {=83516000/Summary!$B$3} -> 83516 | H35: 83516 | I35: {=IF(OR(H35="",G35=""),"",IF(H35=0,IF(G35=0,0,1),(G35-H35)/ABS(H35)))} -> 0 | J35: {=IF(I35="","",IF(ABS(I35)<=Summary!$B$4,1,0))} -> 1 | M35: balance:29
A36: Deferred income taxes | B36: us-gaap_DeferredIncomeTaxLiabilitiesNet | C36: {=665361000/Summary!$B$3} -> 665361 | D36: 665361 | E36: {=IF(OR(D36="",C36=""),"",IF(D36=0,IF(C36=0,0,1),(C36-D36)/ABS(D36)))} -> 0 | F36: {=IF(E36="","",IF(ABS(E36)<=Summary!$B$4,1,0))} -> 1 | G36: {=756869000/Summary!$B$3} -> 756869 | H36: 756869 | I36: {=IF(OR(H36="",G36=""),"",IF(H36=0,IF(G36=0,0,1),(G36-H36)/ABS(H36)))} -> 0 | J36: {=IF(I36="","",IF(ABS(I36)<=Summary!$B$4,1,0))} -> 1 | M36: balance:30
A37: Total liabilities | B37: us-gaap_Liabilities | C37: {=15193917000/Summary!$B$3} -> 15193917 | D37: {=SUM(D32:D36)} -> 15193917 | E37: {=IF(OR(D37="",C37=""),"",IF(D37=0,IF(C37=0,0,1),(C37-D37)/ABS(D37)))} -> 0 | F37: {=IF(E37="","",IF(ABS(E37)<=Summary!$B$4,1,0))} -> 1 | G37: {=16321665000/Summary!$B$3} -> 16321665 | H37: {=SUM(H32:H36)} -> 16321665 | I37: {=IF(OR(H37="",G37=""),"",IF(H37=0,IF(G37=0,0,1),(G37-H37)/ABS(H37)))} -> 0 | J37: {=IF(I37="","",IF(ABS(I37)<=Summary!$B$4,1,0))} -> 1 | M37: balance:31
A38: Commitments and contingencies
A39: Noncontrolling interests subject to put provisions | B39: us-gaap_RedeemableNoncontrollingInterestEquityCarryingAmount | C39: {=1695483000/Summary!$B$3} -> 1695483 | D39: 1695483 | E39: {=IF(OR(D39="",C39=""),"",IF(D39=0,IF(C39=0,0,1),(C39-D39)/ABS(D39)))} -> 0 | F39: {=IF(E39="","",IF(ABS(E39)<=Summary!$B$4,1,0))} -> 1 | G39: {=1532166000/Summary!$B$3} -> 1532166 | H39: 1532166 | I39: {=IF(OR(H39="",G39=""),"",IF(H39=0,IF(G39=0,0,1),(G39-H39)/ABS(H39)))} -> 0 | J39: {=IF(I39="","",IF(ABS(I39)<=Summary!$B$4,1,0))} -> 1 | M39: balance:33
A40: Equity:
...

Sheet Cash flow
A1: CONSOLIDATED STATEMENTS OF CASH FLOWS (DaVita Inc.)
A2: As printed in the 10-K filed 2026-02-11: CONSOLIDATED STATEMENTS OF CASH FLOWS - USD ($) $ in Thousands. Yellow = type the 10-K figure. Blue = the tool's figure. Red = outside the target.
A3: Open this statement on SEC.gov
C4: FY2024 | G4: FY2025
A5: Line | B5: XBRL tag | C5: Tool | D5: 10-K | E5: Diff | F5: OK | G5: Tool | H5: 10-K | I5: Diff | J5: OK | K5: Page / note | L5: Note | M5: row id
A6: Cash flows from operating activities:
A7: Net income | B7: us-gaap_ProfitLoss | C7: {=1250737000/Summary!$B$3} -> 1250737 | D7: {='Income statement'!D26} -> 1250737 | E7: {=IF(OR(D7="",C7=""),"",IF(D7=0,IF(C7=0,0,1),(C7-D7)/ABS(D7)))} -> 0 | F7: {=IF(E7="","",IF(ABS(E7)<=Summary!$B$4,1,0))} -> 1 | G7: {=1078716000/Summary!$B$3} -> 1078716 | H7: 1078716 | I7: {=IF(OR(H7="",G7=""),"",IF(H7=0,IF(G7=0,0,1),(G7-H7)/ABS(H7)))} -> 0 | J7: {=IF(I7="","",IF(ABS(I7)<=Summary!$B$4,1,0))} -> 1 | M7: cashflow:1
A8: Adjustment to Reconcile Net Income to Cash Provided by (Used in) Operating Activity [Abstract]
A9: Depreciation and amortization | B9: us-gaap_DepreciationAmortizationAndAccretionNet | C9: {=723860000/Summary!$B$3} -> 723860 | D9: 723860 | E9: {=IF(OR(D9="",C9=""),"",IF(D9=0,IF(C9=0,0,1),(C9-D9)/ABS(D9)))} -> 0 | F9: {=IF(E9="","",IF(ABS(E9)<=Summary!$B$4,1,0))} -> 1 | G9: {=715348000/Summary!$B$3} -> 715348 | H9: 715348 | I9: {=IF(OR(H9="",G9=""),"",IF(H9=0,IF(G9=0,0,1),(G9-H9)/ABS(H9)))} -> 0 | J9: {=IF(I9="","",IF(ABS(I9)<=Summary!$B$4,1,0))} -> 1 | M9: cashflow:3
A10: Impairment charges | B10: us-gaap_GoodwillAndIntangibleAssetImpairment | C10: {=0/Summary!$B$3} -> 0 | D10: 0 | E10: {=IF(OR(D10="",C10=""),"",IF(D10=0,IF(C10=0,0,1),(C10-D10)/ABS(D10)))} -> 0 | F10: {=IF(E10="","",IF(ABS(E10)<=Summary!$B$4,1,0))} -> 1 | G10: {=0/Summary!$B$3} -> 0 | H10: 0 | I10: {=IF(OR(H10="",G10=""),"",IF(H10=0,IF(G10=0,0,1),(G10-H10)/ABS(H10)))} -> 0 | J10: {=IF(I10="","",IF(ABS(I10)<=Summary!$B$4,1,0))} -> 1 | M10: cashflow:4
A11: Loss on extinguishment of debt | B11: dva_LossOnExtinguishmentOfDebt | C11: {=12527000/Summary!$B$3} -> 12527 | D11: 12527 | E11: {=IF(OR(D11="",C11=""),"",IF(D11=0,IF(C11=0,0,1),(C11-D11)/ABS(D11)))} -> 0 | F11: {=IF(E11="","",IF(ABS(E11)<=Summary!$B$4,1,0))} -> 1 | G11: {=12386000/Summary!$B$3} -> 12386 | H11: 12386 | I11: {=IF(OR(H11="",G11=""),"",IF(H11=0,IF(G11=0,0,1),(G11-H11)/ABS(H11)))} -> 0 | J11: {=IF(I11="","",IF(ABS(I11)<=Summary!$B$4,1,0))} -> 1 | M11: cashflow:5
A12: Stock-based compensation expense | B12: us-gaap_ShareBasedCompensation | C12: {=102788000/Summary!$B$3} -> 102788 | D12: 102788 | E12: {=IF(OR(D12="",C12=""),"",IF(D12=0,IF(C12=0,0,1),(C12-D12)/ABS(D12)))} -> 0 | F12: {=IF(E12="","",IF(ABS(E12)<=Summary!$B$4,1,0))} -> 1 | G12: {=139953000/Summary!$B$3} -> 139953 | H12: 139953 | I12: {=IF(OR(H12="",G12=""),"",IF(H12=0,IF(G12=0,0,1),(G12-H12)/ABS(H12)))} -> 0 | J12: {=IF(I12="","",IF(ABS(I12)<=Summary!$B$4,1,0))} -> 1 | M12: cashflow:6
A13: Deferred income taxes | B13: us-gaap_DeferredIncomeTaxExpenseBenefit | C13: {=-57840000/Summary!$B$3} -> -57840 | D13: -57840 | E13: {=IF(OR(D13="",C13=""),"",IF(D13=0,IF(C13=0,0,1),(C13-D13)/ABS(D13)))} -> 0 | F13: {=IF(E13="","",IF(ABS(E13)<=Summary!$B$4,1,0))} -> 1 | G13: {=86574000/Summary!$B$3} -> 86574 | H13: 86574 | I13: {=IF(OR(H13="",G13=""),"",IF(H13=0,IF(G13=0,0,1),(G13-H13)/ABS(H13)))} -> 0 | J13: {=IF(I13="","",IF(ABS(I13)<=Summary!$B$4,1,0))} -> 1 | M13: cashflow:7
A14: Equity investment loss, net | B14: dva_AdjustmentIncomeLossFromEquityMethodInvestments | C14: {=115839000/Summary!$B$3} -> 115839 | D14: 115839 | E14: {=IF(OR(D14="",C14=""),"",IF(D14=0,IF(C14=0,0,1),(C14-D14)/ABS(D14)))} -> 0 | F14: {=IF(E14="","",IF(ABS(E14)<=Summary!$B$4,1,0))} -> 1 | G14: {=134313000/Summary!$B$3} -> 134313 | H14: 134313 | I14: {=IF(OR(H14="",G14=""),"",IF(H14=0,IF(G14=0,0,1),(G14-H14)/ABS(H14)))} -> 0 | J14: {=IF(I14="","",IF(ABS(I14)<=Summary!$B$4,1,0))} -> 1 | M14: cashflow:8
A15: Gain on changes in ownership interests | B15: us-gaap_BusinessCombinationStepAcquisitionEquityInterestInAcquireeRemeasurementGain | C15: {=-109466000/Summary!$B$3} -> -109466 | D15: -109466 | E15: {=IF(OR(D15="",C15=""),"",IF(D15=0,IF(C15=0,0,1),(C15-D15)/ABS(D15)))} -> 0 | F15: {=IF(E15="","",IF(ABS(E15)<=Summary!$B$4,1,0))} -> 1 | G15: {=0/Summary!$B$3} -> 0 | H15: 0 | I15: {=IF(OR(H15="",G15=""),"",IF(H15=0,IF(G15=0,0,1),(G15-H15)/ABS(H15)))} -> 0 | J15: {=IF(I15="","",IF(ABS(I15)<=Summary!$B$4,1,0))} -> 1 | M15: cashflow:9
A16: Other non-cash (gains) and losses, net | B16: us-gaap_OtherNoncashIncomeExpense | C16: {=13414000/Summary!$B$3} -> 13414 | D16: 13414 | E16: {=IF(OR(D16="",C16=""),"",IF(D16=0,IF(C16=0,0,1),(C16-D16)/ABS(D16)))} -> 0 | F16: {=IF(E16="","",IF(ABS(E16)<=Summary!$B$4,1,0))} -> 1 | G16: {=-17549000/Summary!$B$3} -> -17549 | H16: -17549 | I16: {=IF(OR(H16="",G16=""),"",IF(H16=0,IF(G16=0,0,1),(G16-H16)/ABS(H16)))} -> 0 | J16: {=IF(I16="","",IF(ABS(I16)<=Summary!$B$4,1,0))} -> 1 | M16: cashflow:10
A17: Changes in operating assets and liabilities, net of effect of acquisitions and divestitures:
A18: Accounts receivable | B18: us-gaap_IncreaseDecreaseInAccountsReceivable | C18: {=-29766000/Summary!$B$3} -> -29766 | D18: -29766 | E18: {=IF(OR(D18="",C18=""),"",IF(D18=0,IF(C18=0,0,1),(C18-D18)/ABS(D18)))} -> 0 | F18: {=IF(E18="","",IF(ABS(E18)<=Summary!$B$4,1,0))} -> 1 | G18: {=-210632000/Summary!$B$3} -> -210632 | H18: -210632 | I18: {=IF(OR(H18="",G18=""),"",IF(H18=0,IF(G18=0,0,1),(G18-H18)/ABS(H18)))} -> 0 | J18: {=IF(I18="","",IF(ABS(I18)<=Summary!$B$4,1,0))} -> 1 | M18: cashflow:12
A19: Inventories | B19: us-gaap_IncreaseDecreaseInInventories | C19: {=17942000/Summary!$B$3} -> 17942 | D19: 17942 | E19: {=IF(OR(D19="",C19=""),"",IF(D19=0,IF(C19=0,0,1),(C19-D19)/ABS(D19)))} -> 0 | F19: {=IF(E19="","",IF(ABS(E19)<=Summary!$B$4,1,0))} -> 1 | G19: {=-19950000/Summary!$B$3} -> -19950 | H19: -19950 | I19: {=IF(OR(H19="",G19=""),"",IF(H19=0,IF(G19=0,0,1),(G19-H19)/ABS(H19)))} -> 0 | J19: {=IF(I19="","",IF(ABS(I19)<=Summary!$B$4,1,0))} -> 1 | M19: cashflow:13
A20: Other current assets | B20: dva_IncreaseDecreaseInOtherCurrentReceivablesAndOtherCurrentAssets | C20: {=36801000/Summary!$B$3} -> 36801 | D20: 36801 | E20: {=IF(OR(D20="",C20=""),"",IF(D20=0,IF(C20=0,0,1),(C20-D20)/ABS(D20)))} -> 0 | F20: {=IF(E20="","",IF(ABS(E20)<=Summary!$B$4,1,0))} -> 1 | G20: {=-124297000/Summary!$B$3} -> -124297 | H20: -124297 | I20: {=IF(OR(H20="",G20=""),"",IF(H20=0,IF(G20=0,0,1),(G20-H20)/ABS(H20)))} -> 0 | J20: {=IF(I20="","",IF(ABS(I20)<=Summary!$B$4,1,0))} -> 1 | M20: cashflow:14
A21: Other long-term assets | B21: us-gaap_IncreaseDecreaseInOtherNoncurrentAssets | C21: {=-67031000/Summary!$B$3} -> -67031 | D21: -67031 | E21: {=IF(OR(D21="",C21=""),"",IF(D21=0,IF(C21=0,0,1),(C21-D21)/ABS(D21)))} -> 0 | F21: {=IF(E21="","",IF(ABS(E21)<=Summary!$B$4,1,0))} -> 1 | G21: {=-40253000/Summary!$B$3} -> -40253 | H21: -40253 | I21: {=IF(OR(H21="",G21=""),"",IF(H21=0,IF(G21=0,0,1),(G21-H21)/ABS(H21)))} -> 0 | J21: {=IF(I21="","",IF(ABS(I21)<=Summary!$B$4,1,0))} -> 1 | M21: cashflow:15
A22: Accounts payable | B22: us-gaap_IncreaseDecreaseInAccountsPayable | C22: {=1699000/Summary!$B$3} -> 1699 | D22: 1699 | E22: {=IF(OR(D22="",C22=""),"",IF(D22=0,IF(C22=0,0,1),(C22-D22)/ABS(D22)))} -> 0 | F22: {=IF(E22="","",IF(ABS(E22)<=Summary!$B$4,1,0))} -> 1 | G22: {=128303000/Summary!$B$3} -> 128303 | H22: 128303 | I22: {=IF(OR(H22="",G22=""),"",IF(H22=0,IF(G22=0,0,1),(G22-H22)/ABS(H22)))} -> 0 | J22: {=IF(I22="","",IF(ABS(I22)<=Summary!$B$4,1,0))} -> 1 | M22: cashflow:16
A23: Accrued compensation and benefits | B23: us-gaap_IncreaseDecreaseInEmployeeRelatedLiabilities | C23: {=14687000/Summary!$B$3} -> 14687 | D23: 14687 | E23: {=IF(OR(D23="",C23=""),"",IF(D23=0,IF(C23=0,0,1),(C23-D23)/ABS(D23)))} -> 0 | F23: {=IF(E23="","",IF(ABS(E23)<=Summary!$B$4,1,0))} -> 1 | G23: {=-24042000/Summary!$B$3} -> -24042 | H23: -24042 | I23: {=IF(OR(H23="",G23=""),"",IF(H23=0,IF(G23=0,0,1),(G23-H23)/ABS(H23)))} -> 0 | J23: {=IF(I23="","",IF(ABS(I23)<=Summary!$B$4,1,0))} -> 1 | M23: cashflow:17
A24: Other current liabilities | B24: us-gaap_IncreaseDecreaseInOtherCurrentLiabilities | C24: {=46733000/Summary!$B$3} -> 46733 | D24: 46733 | E24: {=IF(OR(D24="",C24=""),"",IF(D24=0,IF(C24=0,0,1),(C24-D24)/ABS(D24)))} -> 0 | F24: {=IF(E24="","",IF(ABS(E24)<=Summary!$B$4,1,0))} -> 1 | G24: {=-29963000/Summary!$B$3} -> -29963 | H24: -29963 | I24: {=IF(OR(H24="",G24=""),"",IF(H24=0,IF(G24=0,0,1),(G24-H24)/ABS(H24)))} -> 0 | J24: {=IF(I24="","",IF(ABS(I24)<=Summary!$B$4,1,0))} -> 1 | M24: cashflow:18
A25: Income taxes | B25: us-gaap_IncreaseDecreaseInAccruedIncomeTaxesPayable | C25: {=-44214000/Summary!$B$3} -> -44214 | D25: -44214 | E25: {=IF(OR(D25="",C25=""),"",IF(D25=0,IF(C25=0,0,1),(C25-D25)/ABS(D25)))} -> 0 | F25: {=IF(E25="","",IF(ABS(E25)<=Summary!$B$4,1,0))} -> 1 | G25: {=50245000/Summary!$B$3} -> 50245 | H25: 50245 | I25: {=IF(OR(H25="",G25=""),"",IF(H25=0,IF(G25=0,0,1),(G25-H25)/ABS(H25)))} -> 0 | J25: {=IF(I25="","",IF(ABS(I25)<=Summary!$B$4,1,0))} -> 1 | M25: cashflow:19
A26: Other long-term liabilities | B26: us-gaap_IncreaseDecreaseInOtherNoncurrentLiabilities | C26: {=-6672000/Summary!$B$3} -> -6672 | D26: -6672 | E26: {=IF(OR(D26="",C26=""),"",IF(D26=0,IF(C26=0,0,1),(C26-D26)/ABS(D26)))} -> 0 | F26: {=IF(E26="","",IF(ABS(E26)<=Summary!$B$4,1,0))} -> 1 | G26: {=7348000/Summary!$B$3} -> 7348 | H26: 7348 | I26: {=IF(OR(H26="",G26=""),"",IF(H26=0,IF(G26=0,0,1),(G26-H26)/ABS(H26)))} -> 0 | J26: {=IF(I26="","",IF(ABS(I26)<=Summary!$B$4,1,0))} -> 1 | M26: cashflow:20
A27: Net Cash Provided by (Used in) Operating Activities, Total | B27: us-gaap_NetCashProvidedByUsedInOperatingActivities | C27: {=2022038000/Summary!$B$3} -> 2022038 | D27: {=SUM(D7:D26)} -> 2022038 | E27: {=IF(OR(D27="",C27=""),"",IF(D27=0,IF(C27=0,0,1),(C27-D27)/ABS(D27)))} -> 0 | F27: {=IF(E27="","",IF(ABS(E27)<=Summary!$B$4,1,0))} -> 1 | G27: {=1886500000/Summary!$B$3} -> 1886500 | H27: {=SUM(H7:H26)} -> 1886500 | I27: {=IF(OR(H27="",G27=""),"",IF(H27=0,IF(G27=0,0,1),(G27-H27)/ABS(H27)))} -> 0 | J27: {=IF(I27="","",IF(ABS(I27)<=Summary!$B$4,1,0))} -> 1 | M27: cashflow:21
A28: Cash flows from investing activities:
A29: Additions of property and equipment | B29: us-gaap_PaymentsToAcquirePropertyPlantAndEquipment | C29: {=-555443000/Summary!$B$3} -> -555443 | D29: -555443 | E29: {=IF(OR(D29="",C29=""),"",IF(D29=0,IF(C29=0,0,1),(C29-D29)/ABS(D29)))} -> 0 | F29: {=IF(E29="","",IF(ABS(E29)<=Summary!$B$4,1,0))} -> 1 | G29: {=-575864000/Summary!$B$3} -> -575864 | H29: -575864 | I29: {=IF(OR(H29="",G29=""),"",IF(H29=0,IF(G29=0,0,1),(G29-H29)/ABS(H29)))} -> 0 | J29: {=IF(I29="","",IF(ABS(I29)<=Summary!$B$4,1,0))} -> 1 | M29: cashflow:23
A30: Acquisitions | B30: us-gaap_PaymentsToAcquireBusinessesNetOfCashAcquired | C30: {=-246068000/Summary!$B$3} -> -246068 | D30: -246068 | E30: {=IF(OR(D30="",C30=""),"",IF(D30=0,IF(C30=0,0,1),(C30-D30)/ABS(D30)))} -> 0 | F30: {=IF(E30="","",IF(ABS(E30)<=Summary!$B$4,1,0))} -> 1 | G30: {=-117468000/Summary!$B$3} -> -117468 | H30: -117468 | I30: {=IF(OR(H30="",G30=""),"",IF(H30=0,IF(G30=0,0,1),(G30-H30)/ABS(H30)))} -> 0 | J30: {=IF(I30="","",IF(ABS(I30)<=Summary!$B$4,1,0))} -> 1 | M30: cashflow:24
A31: Proceeds from asset and business sales | B31: us-gaap_ProceedsFromSalesOfBusinessAffiliateAndProductiveAssets | C31: {=25862000/Summary!$B$3} -> 25862 | D31: 25862 | E31: {=IF(OR(D31="",C31=""),"",IF(D31=0,IF(C31=0,0,1),(C31-D31)/ABS(D31)))} -> 0 | F31: {=IF(E31="","",IF(ABS(E31)<=Summary!$B$4,1,0))} -> 1 | G31: {=34173000/Summary!$B$3} -> 34173 | H31: 34173 | I31: {=IF(OR(H31="",G31=""),"",IF(H31=0,IF(G31=0,0,1),(G31-H31)/ABS(H31)))} -> 0 | J31: {=IF(I31="","",IF(ABS(I31)<=Summary!$B$4,1,0))} -> 1 | M31: cashflow:25
A32: Purchase of debt investments held-to-maturity | B32: us-gaap_PaymentsToAcquireHeldToMaturitySecurities | C32: {=-15319000/Summary!$B$3} -> -15319 | D32: -15319 | E32: {=IF(OR(D32="",C32=""),"",IF(D32=0,IF(C32=0,0,1),(C32-D32)/ABS(D32)))} -> 0 | F32: {=IF(E32="","",IF(ABS(E32)<=Summary!$B$4,1,0))} -> 1 | G32: {=-16405000/Summary!$B$3} -> -16405 | H32: -16405 | I32: {=IF(OR(H32="",G32=""),"",IF(H32=0,IF(G32=0,0,1),(G32-H32)/ABS(H32)))} -> 0 | J32: {=IF(I32="","",IF(ABS(I32)<=Summary!$B$4,1,0))} -> 1 | M32: cashflow:26
A33: Purchase of other debt and equity investments | B33: dva_PaymentsToAcquireOtherDebtAndEquityInvestments | C33: {=-9140000/Summary!$B$3} -> -9140 | D33: -9140 | E33: {=IF(OR(D33="",C33=""),"",IF(D33=0,IF(C33=0,0,1),(C33-D33)/ABS(D33)))} -> 0 | F33: {=IF(E33="","",IF(ABS(E33)<=Summary!$B$4,1,0))} -> 1 | G33: {=-6031000/Summary!$B$3} -> -6031 | H33: -6031 | I33: {=IF(OR(H33="",G33=""),"",IF(H33=0,IF(G33=0,0,1),(G33-H33)/ABS(H33)))} -> 0 | J33: {=IF(I33="","",IF(ABS(I33)<=Summary!$B$4,1,0))} -> 1 | M33: cashflow:27
A34: Proceeds from debt investments held-to-maturity | B34: us-gaap_ProceedsFromSaleAndMaturityOfHeldToMaturitySecurities | C34: {=22638000/Summary!$B$3} -> 22638 | D34: 22638 | E34: {=IF(OR(D34="",C34=""),"",IF(D34=0,IF(C34=0,0,1),(C34-D34)/ABS(D34)))} -> 0 | F34: {=IF(E34="","",IF(ABS(E34)<=Summary!$B$4,1,0))} -> 1 | G34: {=45413000/Summary!$B$3} -> 45413 | H34: 45413 | I34: {=IF(OR(H34="",G34=""),"",IF(H34=0,IF(G34=0,0,1),(G34-H34)/ABS(H34)))} -> 0 | J34: {=IF(I34="","",IF(ABS(I34)<=Summary!$B$4,1,0))} -> 1 | M34: cashflow:28
A35: Proceeds from sale of other debt and equity investments | B35: us-gaap_ProceedsFromSaleAndMaturityOfOtherInvestments | C35: {=4566000/Summary!$B$3} -> 4566 | D35: 4566 | E35: {=IF(OR(D35="",C35=""),"",IF(D35=0,IF(C35=0,0,1),(C35-D35)/ABS(D35)))} -> 0 | F35: {=IF(E35="","",IF(ABS(E35)<=Summary!$B$4,1,0))} -> 1 | G35: {=6723000/Summary!$B$3} -> 6723 | H35: 6723 | I35: {=IF(OR(H35="",G35=""),"",IF(H35=0,IF(G35=0,0,1),(G35-H35)/ABS(H35)))} -> 0 | J35: {=IF(I35="","",IF(ABS(I35)<=Summary!$B$4,1,0))} -> 1 | M35: cashflow:29
A36: Purchase of equity method investments | B36: us-gaap_PaymentsToAcquireEquityMethodInvestments | C36: {=-5205000/Summary!$B$3} -> -5205 | D36: -5205 | E36: {=IF(OR(D36="",C36=""),"",IF(D36=0,IF(C36=0,0,1),(C36-D36)/ABS(D36)))} -> 0 | F36: {=IF(E36="","",IF(ABS(E36)<=Summary!$B$4,1,0))} -> 1 | G36: {=-27030000/Summary!$B$3} -> -27030 | H36: -27030 | I36: {=IF(OR(H36="",G36=""),"",IF(H36=0,IF(G36=0,0,1),(G36-H36)/ABS(H36)))} -> 0 | J36: {=IF(I36="","",IF(ABS(I36)<=Summary!$B$4,1,0))} -> 1 | M36: cashflow:30
A37: Distributions from equity method investments | B37: us-gaap_ProceedsFromEquityMethodInvestmentDividendsOrDistributionsReturnOfCapital | C37: {=6680000/Summary!$B$3} -> 6680 | D37: 6680 | E37: {=IF(OR(D37="",C37=""),"",IF(D37=0,IF(C37=0,0,1),(C37-D37)/ABS(D37)))} -> 0 | F37: {=IF(E37="","",IF(ABS(E37)<=Summary!$B$4,1,0))} -> 1 | G37: {=1540000/Summary!$B$3} -> 1540 | H37: 1540 | I37: {=IF(OR(H37="",G37=""),"",IF(H37=0,IF(G37=0,0,1),(G37-H37)/ABS(H37)))} -> 0 | J37: {=IF(I37="","",IF(ABS(I37)<=Summary!$B$4,1,0))} -> 1 | M37: cashflow:31
A38: Net Cash Provided by (Used in) Investing Activities, Total | B38: us-gaap_NetCashProvidedByUsedInInvestingActivities | C38: {=-771429000/Summary!$B$3} -> -771429 | D38: {=SUM(D29:D37)} -> -771429 | E38: {=IF(OR(D38="",C38=""),"",IF(D38=0,IF(C38=0,0,1),(C38-D38)/ABS(D38)))} -> 0 | F38: {=IF(E38="","",IF(ABS(E38)<=Summary!$B$4,1,0))} -> 1 | G38: {=-654949000/Summary!$B$3} -> -654949 | H38: {=SUM(H29:H37)} -> -654949 | I38: {=IF(OR(H38="",G38=""),"",IF(H38=0,IF(G38=0,0,1),(G38-H38)/ABS(H38)))} -> 0 | J38: {=IF(I38="","",IF(ABS(I38)<=Summary!$B$4,1,0))} -> 1 | M38: cashflow:32
A39: Cash flows from financing activities:
A40: Borrowings | B40: us-gaap_ProceedsFromIssuanceOfLongTermDebt | C40: {=6624310000/Summary!$B$3} -> 6624310 | D40: 6624310 | E40: {=IF(OR(D40="",C40=""),"",IF(D40=0,IF(C40=0,0,1),(C40-D40)/ABS(D40)))} -> 0 | F40: {=IF(E40="","",IF(ABS(E40)<=Summary!$B$4,1,0))} -> 1 | G40: {=5612280000/Summary!$B$3} -> 5612280 | H40: 5612280 | I40: {=IF(OR(H40="",G40=""),"",IF(H40=0,IF(G40=0,0,1),(G40-H40)/ABS(H40)))} -> 0 | J40: {=IF(I40="","",IF(ABS(I40)<=Summary!$B$4,1,0))} -> 1 | M40: cashflow:34
...

Sheet Notes
A1: Items from the notes (DaVita Inc.)
A2: These come from the XBRL company facts, not the statements. Type them from the notes.
C4: FY2024 | G4: FY2025
A5: Line | B5: XBRL tag / source | C5: Tool | D5: 10-K | E5: Diff | F5: OK | G5: Tool | H5: 10-K | I5: Diff | J5: OK | K5: Page / note | L5: Tool note | M5: row id
A6: Operating lease cost (Leases note: operating lease cost) | B6: OperatingLeaseCost | C6: {=689130000/Summary!$B$3} -> 689130 | E6: {=IF(OR(D6="",C6=""),"",IF(D6=0,IF(C6=0,0,1),(C6-D6)/ABS(D6)))} | F6: {=IF(E6="","",IF(ABS(E6)<=Summary!$B$4,1,0))} | G6: {=702180000/Summary!$B$3} -> 702180 | I6: {=IF(OR(H6="",G6=""),"",IF(H6=0,IF(G6=0,0,1),(G6-H6)/ABS(H6)))} | J6: {=IF(I6="","",IF(ABS(I6)<=Summary!$B$4,1,0))} | M6: notes:operating_lease_cost
A7: Operating lease liabilities, total (Leases note: total operating lease liabilities) | B7: OperatingLeaseLiability | C7: {=2620066000/Summary!$B$3} -> 2620066 | E7: {=IF(OR(D7="",C7=""),"",IF(D7=0,IF(C7=0,0,1),(C7-D7)/ABS(D7)))} | F7: {=IF(E7="","",IF(ABS(E7)<=Summary!$B$4,1,0))} | G7: {=2601142000/Summary!$B$3} -> 2601142 | I7: {=IF(OR(H7="",G7=""),"",IF(H7=0,IF(G7=0,0,1),(G7-H7)/ABS(H7)))} | J7: {=IF(I7="","",IF(ABS(I7)<=Summary!$B$4,1,0))} | M7: notes:operating_lease_liabilities
A8: Debt due in the next 12 months (Debt note: maturities table, first year) | B8: LongTermDebtMaturitiesRepaymentsOfPrincipalInNextTwelveMonths | C8: {=270867000/Summary!$B$3} -> 270867 | E8: {=IF(OR(D8="",C8=""),"",IF(D8=0,IF(C8=0,0,1),(C8-D8)/ABS(D8)))} | F8: {=IF(E8="","",IF(ABS(E8)<=Summary!$B$4,1,0))} | G8: {=109201000/Summary!$B$3} -> 109201 | I8: {=IF(OR(H8="",G8=""),"",IF(H8=0,IF(G8=0,0,1),(G8-H8)/ABS(H8)))} | J8: {=IF(I8="","",IF(ABS(I8)<=Summary!$B$4,1,0))} | M8: notes:scheduled_principal
A9: Cash taxes paid (Cash flow supplemental disclosure or tax note) | B9: IncomeTaxesPaidNet | C9: {=387940000/Summary!$B$3} -> 387940 | E9: {=IF(OR(D9="",C9=""),"",IF(D9=0,IF(C9=0,0,1),(C9-D9)/ABS(D9)))} | F9: {=IF(E9="","",IF(ABS(E9)<=Summary!$B$4,1,0))} | G9: {=176688000/Summary!$B$3} -> 176688 | I9: {=IF(OR(H9="",G9=""),"",IF(H9=0,IF(G9=0,0,1),(G9-H9)/ABS(H9)))} | J9: {=IF(I9="","",IF(ABS(I9)<=Summary!$B$4,1,0))} | M9: notes:cash_taxes

Sheet Ratios
A1: Ratios rebuilt from your typed 10-K figures
A2: Each line adds up the typed statement lines that the standard spread maps to it, with the same signs. A year fills in once its lines are typed. Green = linked cells.
B4: FY2024 | E4: FY2025
A5: Item | B5: From 10-K | C5: Tool | D5: Diff | E5: From 10-K | F5: Tool | G5: Diff
A6: Revenue | B6: {=IF(OR('Income statement'!$D$9=""),"",'Income statement'!$D$9)} -> 12815550 | C6: {=12815550000/Summary!$B$3} -> 12815550 | D6: {=IF(OR(B6="",C6="",B6="n.m."),"",IF(B6=0,"",(C6-B6)/ABS(B6)))} -> 0 | E6: {=IF(OR('Income statement'!$H$9=""),"",'Income statement'!$H$9)} -> 13643069 | F6: {=13643069000/Summary!$B$3} -> 13643069 | G6: {=IF(OR(E6="",F6="",E6="n.m."),"",IF(E6=0,"",(F6-E6)/ABS(E6)))} -> 0
A7: Operating income | B7: {=IF(OR('Income statement'!$D$18=""),"",'Income statement'!$D$18)} -> 2090483 | C7: {=2090483000/Summary!$B$3} -> 2090483 | D7: {=IF(OR(B7="",C7="",B7="n.m."),"",IF(B7=0,"",(C7-B7)/ABS(B7)))} -> 0 | E7: {=IF(OR('Income statement'!$H$18=""),"",'Income statement'!$H$18)} -> 2043615 | F7: {=2043615000/Summary!$B$3} -> 2043615 | G7: {=IF(OR(E7="",F7="",E7="n.m."),"",IF(E7=0,"",(F7-E7)/ABS(E7)))} -> 0
A8: D&A (cash flow statement) | B8: {=IF(OR('Cash flow'!$D$9=""),"",'Cash flow'!$D$9)} -> 723860 | C8: {=723860000/Summary!$B$3} -> 723860 | D8: {=IF(OR(B8="",C8="",B8="n.m."),"",IF(B8=0,"",(C8-B8)/ABS(B8)))} -> 0 | E8: {=IF(OR('Cash flow'!$H$9=""),"",'Cash flow'!$H$9)} -> 715348 | F8: {=715348000/Summary!$B$3} -> 715348 | G8: {=IF(OR(E8="",F8="",E8="n.m."),"",IF(E8=0,"",(F8-E8)/ABS(E8)))} -> 0
A9: EBITDA | B9: {=IF(OR(B7="",B8=""),"",B7+B8)} -> 2814343 | C9: {=2814343000/Summary!$B$3} -> 2814343 | D9: {=IF(OR(B9="",C9="",B9="n.m."),"",IF(B9=0,"",(C9-B9)/ABS(B9)))} -> 0 | E9: {=IF(OR(E7="",E8=""),"",E7+E8)} -> 2758963 | F9: {=2758963000/Summary!$B$3} -> 2758963 | G9: {=IF(OR(E9="",F9="",E9="n.m."),"",IF(E9=0,"",(F9-E9)/ABS(E9)))} -> 0
A10: Interest expense | B10: {=IF(OR('Income statement'!$D$19=""),"",-'Income statement'!$D$19)} -> 470469 | C10: {=470469000/Summary!$B$3} -> 470469 | D10: {=IF(OR(B10="",C10="",B10="n.m."),"",IF(B10=0,"",(C10-B10)/ABS(B10)))} -> 0 | E10: {=IF(OR('Income statement'!$H$19=""),"",-'Income statement'!$H$19)} -> 579926 | F10: {=579926000/Summary!$B$3} -> 579926 | G10: {=IF(OR(E10="",F10="",E10="n.m."),"",IF(E10=0,"",(F10-E10)/ABS(E10)))} -> 0
A11: Total debt | B11: {=IF(OR('Balance sheet'!$D$29="",'Balance sheet'!$D$34=""),"",'Balance sheet'!$D$29+'Balance sheet'!$D$34)} -> 9446770 | C11: {=9446770000/Summary!$B$3} -> 9446770 | D11: {=IF(OR(B11="",C11="",B11="n.m."),"",IF(B11=0,"",(C11-B11)/ABS(B11)))} -> 0 | E11: {=IF(OR('Balance sheet'!$H$29="",'Balance sheet'!$H$34=""),"",'Balance sheet'!$H$29+'Balance sheet'!$H$34)} -> 10273189 | F11: {=10273189000/Summary!$B$3} -> 10273189 | G11: {=IF(OR(E11="",F11="",E11="n.m."),"",IF(E11=0,"",(F11-E11)/ABS(E11)))} -> 0
A12: Cash | B12: {=IF(OR('Balance sheet'!$D$7=""),"",'Balance sheet'!$D$7)} -> 794933 | C12: {=794933000/Summary!$B$3} -> 794933 | D12: {=IF(OR(B12="",C12="",B12="n.m."),"",IF(B12=0,"",(C12-B12)/ABS(B12)))} -> 0 | E12: {=IF(OR('Balance sheet'!$H$7=""),"",'Balance sheet'!$H$7)} -> 676438 | F12: {=676438000/Summary!$B$3} -> 676438 | G12: {=IF(OR(E12="",F12="",E12="n.m."),"",IF(E12=0,"",(F12-E12)/ABS(E12)))} -> 0
A13: Net debt | B13: {=IF(OR(B11="",B12=""),"",B11-B12)} -> 8651837 | C13: {=8651837000/Summary!$B$3} -> 8651837 | D13: {=IF(OR(B13="",C13="",B13="n.m."),"",IF(B13=0,"",(C13-B13)/ABS(B13)))} -> 0 | E13: {=IF(OR(E11="",E12=""),"",E11-E12)} -> 9596751 | F13: {=9596751000/Summary!$B$3} -> 9596751 | G13: {=IF(OR(E13="",F13="",E13="n.m."),"",IF(E13=0,"",(F13-E13)/ABS(E13)))} -> 0
A14: Capex | B14: {=IF(OR('Cash flow'!$D$29=""),"",-'Cash flow'!$D$29)} -> 555443 | C14: {=555443000/Summary!$B$3} -> 555443 | D14: {=IF(OR(B14="",C14="",B14="n.m."),"",IF(B14=0,"",(C14-B14)/ABS(B14)))} -> 0 | E14: {=IF(OR('Cash flow'!$H$29=""),"",-'Cash flow'!$H$29)} -> 575864 | F14: {=575864000/Summary!$B$3} -> 575864 | G14: {=IF(OR(E14="",F14="",E14="n.m."),"",IF(E14=0,"",(F14-E14)/ABS(E14)))} -> 0
A15: Operating lease cost (Notes tab) | B15: {=IF(Notes!$D$6="","",Notes!$D$6)} | C15: {=689130000/Summary!$B$3} -> 689130 | D15: {=IF(OR(B15="",C15="",B15="n.m."),"",IF(B15=0,"",(C15-B15)/ABS(B15)))} | E15: {=IF(Notes!$H$6="","",Notes!$H$6)} | F15: {=702180000/Summary!$B$3} -> 702180 | G15: {=IF(OR(E15="",F15="",E15="n.m."),"",IF(E15=0,"",(F15-E15)/ABS(E15)))}
A16: Operating lease liabilities, total (Notes tab) | B16: {=IF(Notes!$D$7="","",Notes!$D$7)} | C16: {=2620066000/Summary!$B$3} -> 2620066 | D16: {=IF(OR(B16="",C16="",B16="n.m."),"",IF(B16=0,"",(C16-B16)/ABS(B16)))} | E16: {=IF(Notes!$H$7="","",Notes!$H$7)} | F16: {=2601142000/Summary!$B$3} -> 2601142 | G16: {=IF(OR(E16="",F16="",E16="n.m."),"",IF(E16=0,"",(F16-E16)/ABS(E16)))}
A17: Debt due in the next 12 months (Notes tab) | B17: {=IF(Notes!$D$8="","",Notes!$D$8)} | C17: {=270867000/Summary!$B$3} -> 270867 | D17: {=IF(OR(B17="",C17="",B17="n.m."),"",IF(B17=0,"",(C17-B17)/ABS(B17)))} | E17: {=IF(Notes!$H$8="","",Notes!$H$8)} | F17: {=109201000/Summary!$B$3} -> 109201 | G17: {=IF(OR(E17="",F17="",E17="n.m."),"",IF(E17=0,"",(F17-E17)/ABS(E17)))}
A18: Cash taxes paid (Notes tab) | B18: {=IF(Notes!$D$9="","",Notes!$D$9)} | C18: {=387940000/Summary!$B$3} -> 387940 | D18: {=IF(OR(B18="",C18="",B18="n.m."),"",IF(B18=0,"",(C18-B18)/ABS(B18)))} | E18: {=IF(Notes!$H$9="","",Notes!$H$9)} | F18: {=176688000/Summary!$B$3} -> 176688 | G18: {=IF(OR(E18="",F18="",E18="n.m."),"",IF(E18=0,"",(F18-E18)/ABS(E18)))}
A19: EBITDAR | B19: {=IF(OR(B9="",B15=""),"",B9+B15)} | C19: {=3503473000/Summary!$B$3} -> 3503473 | D19: {=IF(OR(B19="",C19="",B19="n.m."),"",IF(B19=0,"",(C19-B19)/ABS(B19)))} | E19: {=IF(OR(E9="",E15=""),"",E9+E15)} | F19: {=3461143000/Summary!$B$3} -> 3461143 | G19: {=IF(OR(E19="",F19="",E19="n.m."),"",IF(E19=0,"",(F19-E19)/ABS(E19)))}
A20: Current assets | B20: {=IF(OR('Balance sheet'!$D$15=""),"",'Balance sheet'!$D$15)} -> 3746072 | C20: {=3746072000/Summary!$B$3} -> 3746072 | D20: {=IF(OR(B20="",C20="",B20="n.m."),"",IF(B20=0,"",(C20-B20)/ABS(B20)))} -> 0 | E20: {=IF(OR('Balance sheet'!$H$15=""),"",'Balance sheet'!$H$15)} -> 4058003 | F20: {=4058003000/Summary!$B$3} -> 4058003 | G20: {=IF(OR(E20="",F20="",E20="n.m."),"",IF(E20=0,"",(F20-E20)/ABS(E20)))} -> 0
A21: Current liabilities | B21: {=IF(OR('Balance sheet'!$D$32=""),"",'Balance sheet'!$D$32)} -> 2973410 | C21: {=2973410000/Summary!$B$3} -> 2973410 | D21: {=IF(OR(B21="",C21="",B21="n.m."),"",IF(B21=0,"",(C21-B21)/ABS(B21)))} -> 0 | E21: {=IF(OR('Balance sheet'!$H$32=""),"",'Balance sheet'!$H$32)} -> 3141634 | F21: {=3141634000/Summary!$B$3} -> 3141634 | G21: {=IF(OR(E21="",F21="",E21="n.m."),"",IF(E21=0,"",(F21-E21)/ABS(E21)))} -> 0
A23: Debt / EBITDA | B23: {=IF(OR(B11="",B9=""),"",IF(B9<=0,"n.m.",(B11)/(B9)))} -> 3.356652 | C23: 3.356652 | D23: {=IF(OR(B23="",C23="",B23="n.m."),"",IF(B23=0,"",(C23-B23)/ABS(B23)))} -> 0 | E23: {=IF(OR(E11="",E9=""),"",IF(E9<=0,"n.m.",(E11)/(E9)))} -> 3.723569 | F23: 3.723569 | G23: {=IF(OR(E23="",F23="",E23="n.m."),"",IF(E23=0,"",(F23-E23)/ABS(E23)))} -> 0
A24: Net debt / EBITDA | B24: {=IF(OR(B13="",B9=""),"",IF(B9<=0,"n.m.",(B13)/(B9)))} -> 3.0741942 | C24: 3.0741942 | D24: {=IF(OR(B24="",C24="",B24="n.m."),"",IF(B24=0,"",(C24-B24)/ABS(B24)))} -> 0 | E24: {=IF(OR(E13="",E9=""),"",IF(E9<=0,"n.m.",(E13)/(E9)))} -> 3.4783906 | F24: 3.4783906 | G24: {=IF(OR(E24="",F24="",E24="n.m."),"",IF(E24=0,"",(F24-E24)/ABS(E24)))} -> 0
A25: (Debt + leases) / EBITDAR | B25: {=IF(OR(B11="",B16="",B19=""),"",IF(B19<=0,"n.m.",(B11+B16)/(B19)))} | C25: 3.4442497 | D25: {=IF(OR(B25="",C25="",B25="n.m."),"",IF(B25=0,"",(C25-B25)/ABS(B25)))} | E25: {=IF(OR(E11="",E16="",E19=""),"",IF(E19<=0,"n.m.",(E11+E16)/(E19)))} | F25: 3.7196761 | G25: {=IF(OR(E25="",F25="",E25="n.m."),"",IF(E25=0,"",(F25-E25)/ABS(E25)))}
A26: EBITDA / interest | B26: {=IF(OR(B9="",B10=""),"",IF(B10<=0,"n.m.",(B9)/(B10)))} -> 5.9819946 | C26: 5.9819946 | D26: {=IF(OR(B26="",C26="",B26="n.m."),"",IF(B26=0,"",(C26-B26)/ABS(B26)))} -> 0 | E26: {=IF(OR(E9="",E10=""),"",IF(E10<=0,"n.m.",(E9)/(E10)))} -> 4.7574397 | F26: 4.7574397 | G26: {=IF(OR(E26="",F26="",E26="n.m."),"",IF(E26=0,"",(F26-E26)/ABS(E26)))} -> 0
A27: DSCR | B27: {=IF(OR(B9="",B14="",B18="",B10="",B17=""),"",IF(B10+B17<=0,"n.m.",(B9-B14-B18)/(B10+B17)))} | C27: 2.5237679 | D27: {=IF(OR(B27="",C27="",B27="n.m."),"",IF(B27=0,"",(C27-B27)/ABS(B27)))} | E27: {=IF(OR(E9="",E14="",E18="",E10="",E17=""),"",IF(E10+E17<=0,"n.m.",(E9-E14-E18)/(E10+E17)))} | F27: 2.9115257 | G27: {=IF(OR(E27="",F27="",E27="n.m."),"",IF(E27=0,"",(F27-E27)/ABS(E27)))}
A28: Current ratio | B28: {=IF(OR(B20="",B21=""),"",IF(B21<=0,"n.m.",(B20)/(B21)))} -> 1.2598572 | C28: 1.2598572 | D28: {=IF(OR(B28="",C28="",B28="n.m."),"",IF(B28=0,"",(C28-B28)/ABS(B28)))} -> 0 | E28: {=IF(OR(E20="",E21=""),"",IF(E21<=0,"n.m.",(E20)/(E21)))} -> 1.2916855 | F28: 1.2916855 | G28: {=IF(OR(E28="",F28="",E28="n.m."),"",IF(E28=0,"",(F28-E28)/ABS(E28)))} -> 0
